Workbook

Sheet Replacement_Candidates_CLEAN
A1: EMERGENCY REPLACEMENT CANDIDATES — STAFF VIEW
A2: Auto-filtered. Emergency orders only. Sorted by Final Priority Score.
A4: Order ID | B4: Grinder Name | C4: Tier | D4: Effective Bid | E4: Delivery Days | F4: Margin% | G4: Final Score | H4: WHY | I4: Recommended
A5: =IFERROR(__xludf.DUMMYFUNCTION("LET(data,Queue_All!A6:AZ500,hdr,Queue_All!A5:AZ5,eflag,Queue_All!AN6:AN500,score,Queue_All!AC6:AC500,filtered,FILTER(data,eflag=1),sorted,SORTBY(filtered,score,-1),CHOOSECOLS(sorted,MATCH(""OrderID"",hdr,0),MATCH(""GrinderName"",hdr,0),MATCH(""Tier"",hdr,"&"0),MATCH(""EffectiveBidAmount"",hdr,0),MATCH(""DeliveryDays"",hdr,0),MATCH(""Margin%"",hdr,0),MATCH(""FinalPriorityScore"",hdr,0),MATCH(""WHY"",hdr,0)))"),"#VALUE!") -> #VALUE! | I5: =IF($A5="","",IF(ROW()=5,"✅ Recommended","")) -> #VALUE!
I6: =IF($A6="","",IF(ROW()=5,"✅ Recommended",""))
I7: =IF($A7="","",IF(ROW()=5,"✅ Recommended",""))
I8: =IF($A8="","",IF(ROW()=5,"✅ Recommended",""))
I9: =IF($A9="","",IF(ROW()=5,"✅ Recommended",""))
I10: =IF($A10="","",IF(ROW()=5,"✅ Recommended",""))
I11: =IF($A11="","",IF(ROW()=5,"✅ Recommended",""))
I12: =IF($A12="","",IF(ROW()=5,"✅ Recommended",""))
I13: =IF($A13="","",IF(ROW()=5,"✅ Recommended",""))
I14: =IF($A14="","",IF(ROW()=5,"✅ Recommended",""))
I15: =IF($A15="","",IF(ROW()=5,"✅ Recommended",""))
I16: =IF($A16="","",IF(ROW()=5,"✅ Recommended",""))
I17: =IF($A17="","",IF(ROW()=5,"✅ Recommended",""))
... I504: =IF($A504="","",IF(ROW()=5,"✅ Recommended",""))

Sheet Replacement_Queue
A1: EMERGENCY REPLACEMENT QUEUE (auto)
A2: (Shows only Queue_All rows where EmergencyFlag=1. If you see 'No emergency orders', there are none.)
A4: =Queue_All!A5:AO5 -> QUEUE POSITION
A5: =IFERROR(__xludf.DUMMYFUNCTION("LET(data,Queue_All!A6:AO500,flag,Queue_All!AN6:AN500,FILTER(data,flag=1,""No emergency orders""))"),"#N/A") -> #N/A

Sheet Replacement_Candidates
A1: EMERGENCY REPLACEMENT CANDIDATES (Top 5 per order)
A2: Auto-built from Queue_All where EmergencyFlag=1. Shows top 5 grinders by FinalPriorityScore for each emergency order.
A4: =IFERROR(__xludf.DUMMYFUNCTION("LET( data,Queue_All!A6:CA500, flag,Queue_All!AN6:AN500, ordcol,Queue_All!C6:C500, scorecol,Queue_All!AC6:AC500, orders,UNIQUE(FILTER(ordcol,flag=1)), header,Queue_All!A5:CA5, REDUCE(header,orders,LAMBDA(acc,o, LET( rows,FILTER(data,(ordcol=o)*(flag=1),"""&"""), scores,FILTER(scorecol,(ordcol=o)*(flag=1),""""), top,TAKE(SORTBY(rows,scores,-1),5), VSTACK(acc,"""",HSTACK(""ORDER:"",o),top) ) )) )"),"QUEUE POSITION") -> QUEUE POSITION | B4: =IFERROR(__xludf.DUMMYFUNCTION("""COMPUTED_VALUE"""),"BidID") -> BidID | C4: =IFERROR(__xludf.DUMMYFUNCTION("""COMPUTED_VALUE"""),"OrderID") -> OrderID | D4: =IFERROR(__xludf.DUMMYFUNCTION("""COMPUTED_VALUE"""),"OrderStatus") -> OrderStatus | E4: =IFERROR(__xludf.DUMMYFUNCTION("""COMPUTED_VALUE"""),"Service") -> Service | F4: =IFERROR(__xludf.DUMMYFUNCTION("""COMPUTED_VALUE"""),"CustomerPrice") -> CustomerPrice | G4: =IFERROR(__xludf.DUMMYFUNCTION("""COMPUTED_VALUE"""),"DueDateTime") -> DueDateTime | H4: =IFERROR(__xludf.DUMMYFUNCTION("""COMPUTED_VALUE"""),"Rush") -> Rush | I4: =IFERROR(__xludf.DUMMYFUNCTION("""COMPUTED_VALUE"""),"Complexity") -> Complexity | J4: =IFERROR(__xludf.DUMMYFUNCTION("""COMPUTED_VALUE"""),"GrinderID") -> GrinderID | K4: =IFERROR(__xludf.DUMMYFUNCTION("""COMPUTED_VALUE"""),"GrinderName") -> GrinderName | L4: =IFERROR(__xludf.DUMMYFUNCTION("""COMPUTED_VALUE"""),"Tier") -> Tier | M4: =IFERROR(__xludf.DUMMYFUNCTION("""COMPUTED_VALUE"""),"Capacity") -> Capacity | N4: =IFERROR(__xludf.DUMMYFUNCTION("""COMPUTED_VALUE"""),"ActiveOrders") -> ActiveOrders | O4: =IFERROR(__xludf.DUMMYFUNCTION("""COMPUTED_VALUE"""),"Utilization") -> Utilization | P4: =IFERROR(__xludf.DUMMYFUNCTION("""COMPUTED_VALUE"""),"OrdersAssigned7d") -> OrdersAssigned7d | Q4: =IFERROR(__xludf.DUMMYFUNCTION("""COMPUTED_VALUE"""),"DaysIdle") -> DaysIdle | R4: =IFERROR(__xludf.DUMMYFUNCTION("""COMPUTED_VALUE"""),"FairnessScore") -> FairnessScore | S4: =IFERROR(__xludf.DUMMYFUNCTION("""COMPUTED_VALUE"""),"BidAmount") -> BidAmount | T4: =IFERROR(__xludf.DUMMYFUNCTION("""COMPUTED_VALUE"""),"EstDeliveryDateTime") -> EstDeliveryDateTime | U4: =IFERROR(__xludf.DUMMYFUNCTION("""COMPUTED_VALUE"""),"Margin%") -> Margin% | V4: =IFERROR(__xludf.DUMMYFUNCTION("""COMPUTED_VALUE"""),"ProfitScore") -> ProfitScore | W4: =IFERROR(__xludf.DUMMYFUNCTION("""COMPUTED_VALUE"""),"TierScore") -> TierScore | X4: =IFERROR(__xludf.DUMMYFUNCTION("""COMPUTED_VALUE"""),"DeliveryScore") -> DeliveryScore | Y4: =IFERROR(__xludf.DUMMYFUNCTION("""COMPUTED_VALUE"""),"QualityScore") -> QualityScore | Z4: =IFERROR(__xludf.DUMMYFUNCTION("""COMPUTED_VALUE"""),"ReliabilityScore") -> ReliabilityScore | AA4: =IFERROR(__xludf.DUMMYFUNCTION("""COMPUTED_VALUE"""),"RiskScore") -> RiskScore | AB4: =IFERROR(__xludf.DUMMYFUNCTION("""COMPUTED_VALUE"""),"Eligible") -> Eligible | AC4: =IFERROR(__xludf.DUMMYFUNCTION("""COMPUTED_VALUE"""),"FinalPriorityScore") -> FinalPriorityScore | AD4: =IFERROR(__xludf.DUMMYFUNCTION("""COMPUTED_VALUE"""),"RankWithinOrder") -> RankWithinOrder | AE4: =IFERROR(__xludf.DUMMYFUNCTION("""COMPUTED_VALUE"""),"WinnerFlag") -> WinnerFlag | AF4: =IFERROR(__xludf.DUMMYFUNCTION("""COMPUTED_VALUE"""),"Why_Breakdown") -> Why_Breakdown | AG4: =IFERROR(__xludf.DUMMYFUNCTION("""COMPUTED_VALUE"""),"LifetimeAssigned") -> LifetimeAssigned | AH4: =IFERROR(__xludf.DUMMYFUNCTION("""COMPUTED_VALUE"""),"NewGrinderBonus") -> NewGrinderBonus | AI4: =IFERROR(__xludf.DUMMYFUNCTION("""COMPUTED_VALUE"""),"HighValueEliteBonus") -> HighValueEliteBonus | AK4: =IFERROR(__xludf.DUMMYFUNCTION("""COMPUTED_VALUE"""),"StrikePenalty") -> StrikePenalty | AL4: =IFERROR(__xludf.DUMMYFUNCTION("""COMPUTED_VALUE"""),"StrikeLockout") -> StrikeLockout | AM4: =IFERROR(__xludf.DUMMYFUNCTION("""COMPUTED_VALUE"""),"CounterPending") -> CounterPending | AN4: =IFERROR(__xludf.DUMMYFUNCTION("""COMPUTED_VALUE"""),"EmergencyFlag") -> EmergencyFlag | AO4: =IFERROR(__xludf.DUMMYFUNCTION("""COMPUTED_VALUE"""),"EmergencyBoost") -> EmergencyBoost
A5: =IFERROR(__xludf.DUMMYFUNCTION("""COMPUTED_VALUE"""),"") | B5: =IFERROR(__xludf.DUMMYFUNCTION("""COMPUTED_VALUE"""),"#N/A") -> #N/A | C5: =IFERROR(__xludf.DUMMYFUNCTION("""COMPUTED_VALUE"""),"#N/A") -> #N/A | D5: =IFERROR(__xludf.DUMMYFUNCTION("""COMPUTED_VALUE"""),"#N/A") -> #N/A | E5: =IFERROR(__xludf.DUMMYFUNCTION("""COMPUTED_VALUE"""),"#N/A") -> #N/A | F5: =IFERROR(__xludf.DUMMYFUNCTION("""COMPUTED_VALUE"""),"#N/A") -> #N/A | G5: =IFERROR(__xludf.DUMMYFUNCTION("""COMPUTED_VALUE"""),"#N/A") -> #N/A | H5: =IFERROR(__xludf.DUMMYFUNCTION("""COMPUTED_VALUE"""),"#N/A") -> #N/A | I5: =IFERROR(__xludf.DUMMYFUNCTION("""COMPUTED_VALUE"""),"#N/A") -> #N/A | ... AO5: =IFERROR(__xludf.DUMMYFUNCTION("""COMPUTED_VALUE"""),"#N/A") -> #N/A
A6: =IFERROR(__xludf.DUMMYFUNCTION("""COMPUTED_VALUE"""),"ORDER:") -> ORDER: | B6: =IFERROR(__xludf.DUMMYFUNCTION("""COMPUTED_VALUE"""),"#N/A") -> #N/A | C6: =IFERROR(__xludf.DUMMYFUNCTION("""COMPUTED_VALUE"""),"#N/A") -> #N/A | D6: =IFERROR(__xludf.DUMMYFUNCTION("""COMPUTED_VALUE"""),"#N/A") -> #N/A | E6: =IFERROR(__xludf.DUMMYFUNCTION("""COMPUTED_VALUE"""),"#N/A") -> #N/A | F6: =IFERROR(__xludf.DUMMYFUNCTION("""COMPUTED_VALUE"""),"#N/A") -> #N/A | G6: =IFERROR(__xludf.DUMMYFUNCTION("""COMPUTED_VALUE"""),"#N/A") -> #N/A | H6: =IFERROR(__xludf.DUMMYFUNCTION("""COMPUTED_VALUE"""),"#N/A") -> #N/A | I6: =IFERROR(__xludf.DUMMYFUNCTION("""COMPUTED_VALUE"""),"#N/A") -> #N/A | ... AO6: =IFERROR(__xludf.DUMMYFUNCTION("""COMPUTED_VALUE"""),"#N/A") -> #N/A
A7: =IFERROR(__xludf.DUMMYFUNCTION("""COMPUTED_VALUE"""),"#NAME?") -> #NAME? | B7: =IFERROR(__xludf.DUMMYFUNCTION("""COMPUTED_VALUE"""),"#N/A") -> #N/A | C7: =IFERROR(__xludf.DUMMYFUNCTION("""COMPUTED_VALUE"""),"#N/A") -> #N/A | D7: =IFERROR(__xludf.DUMMYFUNCTION("""COMPUTED_VALUE"""),"#N/A") -> #N/A | E7: =IFERROR(__xludf.DUMMYFUNCTION("""COMPUTED_VALUE"""),"#N/A") -> #N/A | F7: =IFERROR(__xludf.DUMMYFUNCTION("""COMPUTED_VALUE"""),"#N/A") -> #N/A | G7: =IFERROR(__xludf.DUMMYFUNCTION("""COMPUTED_VALUE"""),"#N/A") -> #N/A | H7: =IFERROR(__xludf.DUMMYFUNCTION("""COMPUTED_VALUE"""),"#N/A") -> #N/A | I7: =IFERROR(__xludf.DUMMYFUNCTION("""COMPUTED_VALUE"""),"#N/A") -> #N/A | ... AO7: =IFERROR(__xludf.DUMMYFUNCTION("""COMPUTED_VALUE"""),"#N/A") -> #N/A

Sheet README
A1: Grinder Orders Priority Queue — Template
A3: Quick start
A5: 1) Fill Services, Grinders, GrinderServices (eligibility).
A6: 2) Log Orders. Enter Bids as they come in.
A7: 3) Use Queue_All for global dispatch; Queue_Service for a specific service subset.
A8: 4) Log awarded orders in Assignments to update load balancing and performance history.
A9: 5) Tune weights + guardrails in Config (blue cells are inputs).

Sheet Config
A1: Config / Tuning
A3: AsOfDate | B3: 46071
A5: Weights (0–1, sum to 1.0) | C5: w/data
A6: ProfitWeight | B6: 0.4 | C6: 0.33
A7: FairnessWeight | B7: 0.36 | C7: 0.27
A8: TierWeight | B8: 0.04 | C8: 0.05
A9: DeliveryWeight | B9: 0.15 | C9: 0.13
A10: QualityWeight | B10: 0.05 | C10: 0.07
A11: ReliabilityWeight | B11: 0 | C11: 0.1
A12: RiskWeight | B12: 0 | C12: 0.05
A13: TotalWeight | B13: =SUM(B6:B12) -> 1 | C13: =SUM(C6:C12) -> 1
A15: Guardrails
A16: MinMarginPct | B16: 0.25
A17: TargetMarginPct | B17: 0.35
A18: OverCapacityDisqualify | B18: 1
A19: LateToleranceHours | B19: 24
A20: EarlyBonusHours | B20: 24
A21: EliteBonusPoints | B21: =B39 -> 8
A22: MaxFairnessIdleBonus | B22: 15
A23: IdleBonusFullAfterDays | B23: 7
A26: Fairness components
A27: Fair_LoadWeight | B27: 0.55
A28: Fair_Recent7dWeight | B28: 0.3
A29: Fair_IdleWeight | B29: 0.15
A30: Fair_TargetOrders7d | B30: =B38 -> 1
A32: Scale / Auto-Tuning Inputs
A33: DailyOrdersAssumption | B33: 3
A34: TotalGrinders | B34: =COUNTA(Grinders!$A$4:$A$998) -> 73
A35: EliteCount | B35: =COUNTIF(Grinders!$C$4:$C$998,"Elite") -> 8
A36: EliteShare | B36: =IF(B34=0,0,B35/B34) -> 0.10958904
A37: WeeklyOrdersAssumption | B37: =B33*7 -> 21
A38: Auto_TargetOrders7d | B38: =MAX(1,ROUND(B37/B34,0)) -> 1
A39: Auto_EliteBonusPoints | B39: =MAX(4,MIN(8,ROUND(9-8*B36,0))) -> 8
A41: LargeOrderThreshold | B41: 500
A42: LargeOrderEliteBonusPoints | B42: 2
A43: NewGrinderBonusPoints | B43: 2
A1001: Strike3_HighValueThreshold | B1001: 500
A1002: Strike3_LockoutServices | B1002: REP GRINDING,BADGE GRINDING,EVENT GRINDING
A1003: Strike3_LockoutEnabled | B1003: Y
A1004: StrikeExpireEnabled | B1004: Y
...

Sheet Services
A1: Services
A3: Service Name | B3: Service Group | C3: Default Complexity (1-5) | D3: SLA_Days | E3: Notes
A4: Rep Grinding ⚡ | B4: Rep | C4: 5 | D4: 7 | E4: —
A5: Badge Grinding 🎖️ | B5: Badges | C5: 2 | D5: 5 | E5: —
A6: Hot Zones 🔥 | B6: MyPlayer Perks | C6: 1 | D6: 1 | E6: —
A7: Build Specializations 🛠️ | B7: MyPlayer Perks | C7: 2 | D7: 10 | E7: —
A8: Lifetime Challenges 🏆 | B8: MyPlayer Perks | C8: 5 | D8: 14 | E8: —
A9: Plate Card Grinding 🃏 | B9: MyPlayer Perks | C9: 3 | D9: 2 | E9: —
A10: VC Grinding 🪙 | B10: VC | C10: 1 | D10: 5 | E10: —
A11: Event Grinding 🏟️ | B11: Events | C11: 5 | D11: 3 | E11: —
A12: Bundle Order 🎁 | B12: Bundle | C12: 5 | D12: 10 | E12: —
A13: Season Pass Grinding 🎫 | B13: MyPlayer Perks | C13: 2 | D13: 7 | E13: —
A14: Add-Ons ➕ | B14: Other | C14: 1 | D14: 2 | E14: —

Sheet Grinders
A1: Grinders | R1: =IF(A4="","",IFERROR(AVERAGEIFS(Assignments!$J:$J,Assignments!$B:$B,A4,Assignments!$E:$E,"Completed"),""))
A3: Grinder ID | B3: Grinder | C3: Tier | D3: Capacity | E3: Active Orders | F3: Orders Assigned L-7D | G3: Last Assigned | H3: Days Since Last Assigned | I3: Utilization | J3: Avg Quality Rating (1-5) | K3: On Time Rate | L3: Cancel Rate | M3: Avg Turnaround Days | N3: Notes | P3: Strikes(0-3) | Q3: StrikePenalty | R3: AvgMargin% | S3: Reassignments_AsOriginal_30d | T3: Saves_AsReplacement_30d | U3: ReassignRate_30d | V3: NetReassignScore
A4: GRD-01 | B4: 7unds | C4: Regular | D4: =IF($C4="Regular","3","5") -> 3 | E4: =IF($A4="","",COUNTIFS(Assignments!$B$6:$B$305,$A4,Assignments!$E$6:$E$305,"Active")) -> 1 | F4: =IF($A4="","",COUNTIFS(Assignments!$B$6:$B$305,$A4,Assignments!$D$6:$D$305,">="&Config!$B$3-7,Assignments!$D$6:$D$305,"<="&Config!$B$3)) -> 0 | G4: =IF($A4="","",MAXIFS(Assignments!$D$6:$D$305,Assignments!$B$6:$B$305,$A4)) -> 46074 | H4: =IF($A4="","",IF($G4="","",Config!$B$3-$G4)) -> -3 | I4: =IF($A4="","",IF($D4=0,"",$E4/$D4)) -> 0.33333333 | J4: =IF($A4="","",IFERROR(AVERAGEIFS(Assignments!$N$6:$N$1000,Assignments!$B$6:$B$1000,$A4,Assignments!$E$6:$E$1000,"Completed"),"")) | K4: =IF($A4="","",IFERROR(AVERAGEIFS(Assignments!$AO:$AO,Assignments!$B:$B,$A4,Assignments!$E:$E,"Completed"),"")) | L4: =IF($A4="","",IFERROR(COUNTIFS(Assignments!$B$6:$B$1000,$A4,Assignments!$E$6:$E$1000,"Cancelled")/MAX(1,COUNTIFS(Assignments!$B$6:$B$1000,$A4,Assignments!$E$6:$E$1000,"Completed")+COUNTIFS(Assignments!$B$6:$B$1000,$A4,Assignments!$E$6:$E$1000,"Cancelled")),"")) -> 0 | M4: =IF($A4="","",IFERROR(AVERAGEIFS(Assignments!$P$6:$P$1000,Assignments!$B$6:$B$1000,$A4,Assignments!$E$6:$E$1000,"Completed"),"")) | N4: - | P4: =IF(A4="","",MAX(0,MIN(3,SUMIFS(Strike_Log!$C:$C,Strike_Log!$B:$B,A4,Strike_Log!$A:$A,">="&IF(Config!$B$1004="Y",TODAY()-Config!$B$1005,DATE(1900,1,1)),Strike_Log!$I:$I,1)))) -> 0 | Q4: =IF(P4="",0,CHOOSE(MIN(3,MAX(0,P4))+1,0,0.03,0.07,0.2)) -> 0 | S4: =IF(A4="","",COUNTIFS(Assignments!$B:$B,A4,Assignments!$AE:$AE, "Y",Assignments!$D:$D,">="&TODAY()-30)) -> 0 | T4: =IF(A4="","",COUNTIFS(Assignments!$AF:$AF,A4,Assignments!$AE:$AE, "Y",Assignments!$D:$D,">="&TODAY()-30)) -> 0 | U4: =IF(A4="","",IFERROR(S4/MAX(1,COUNTIFS(Assignments!$B:$B,A4,Assignments!$D:$D,">="&TODAY()-30)),"")) -> 0 | V4: =IF(A4="","",T4-S4) -> 0
A5: GRD-02 | B5: 8fy1 | C5: Regular | D5: =IF($C5="Regular","3","5") -> 3 | E5: =IF($A5="","",COUNTIFS(Assignments!$B$6:$B$305,$A5,Assignments!$E$6:$E$305,"Active")) -> 0 | F5: =IF($A5="","",COUNTIFS(Assignments!$B$6:$B$305,$A5,Assignments!$D$6:$D$305,">="&Config!$B$3-7,Assignments!$D$6:$D$305,"<="&Config!$B$3)) -> 0 | G5: =IF($A5="","",MAXIFS(Assignments!$D$6:$D$305,Assignments!$B$6:$B$305,$A5)) -> 0 | H5: =IF($A5="","",IF($G5="","",Config!$B$3-$G5)) -> 46071 | I5: =IF($A5="","",IF($D5=0,"",$E5/$D5)) -> 0 | J5: =IF($A5="","",IFERROR(AVERAGEIFS(Assignments!$N$6:$N$1000,Assignments!$B$6:$B$1000,$A5,Assignments!$E$6:$E$1000,"Completed"),"")) | K5: =IF($A5="","",IFERROR(AVERAGEIFS(Assignments!$AO:$AO,Assignments!$B:$B,$A5,Assignments!$E:$E,"Completed"),"")) | L5: =IF($A5="","",IFERROR(COUNTIFS(Assignments!$B$6:$B$1000,$A5,Assignments!$E$6:$E$1000,"Cancelled")/MAX(1,COUNTIFS(Assignments!$B$6:$B$1000,$A5,Assignments!$E$6:$E$1000,"Completed")+COUNTIFS(Assignments!$B$6:$B$1000,$A5,Assignments!$E$6:$E$1000,"Cancelled")),"")) -> 0 | M5: =IF($A5="","",IFERROR(AVERAGEIFS(Assignments!$P$6:$P$1000,Assignments!$B$6:$B$1000,$A5,Assignments!$E$6:$E$1000,"Completed"),"")) | N5: - | P5: =IF(A5="","",MAX(0,MIN(3,SUMIFS(Strike_Log!$C:$C,Strike_Log!$B:$B,A5,Strike_Log!$A:$A,">="&IF(Config!$B$1004="Y",TODAY()-Config!$B$1005,DATE(1900,1,1)),Strike_Log!$I:$I,1)))) -> 0 | Q5: =IF(P5="",0,CHOOSE(MIN(3,MAX(0,P5))+1,0,0.03,0.07,0.2)) -> 0 | R5: =IF(A5="","",IFERROR(AVERAGEIFS(Assignments!$J:$J,Assignments!$B:$B,A5,Assignments!$E:$E,"Completed"),"")) | S5: =IF(A5="","",COUNTIFS(Assignments!$B:$B,A5,Assignments!$AE:$AE, "Y",Assignments!$D:$D,">="&TODAY()-30)) -> 0 | T5: =IF(A5="","",COUNTIFS(Assignments!$AF:$AF,A5,Assignments!$AE:$AE, "Y",Assignments!$D:$D,">="&TODAY()-30)) -> 0 | U5: =IF(A5="","",IFERROR(S5/MAX(1,COUNTIFS(Assignments!$B:$B,A5,Assignments!$D:$D,">="&TODAY()-30)),"")) -> 0 | V5: =IF(A5="","",T5-S5) -> 0
A6: GRD-03 | B6: ahdedazs | C6: Regular | D6: =IF($C6="Regular","3","5") -> 3 | E6: =IF($A6="","",COUNTIFS(Assignments!$B$6:$B$305,$A6,Assignments!$E$6:$E$305,"Active")) -> 0 | F6: =IF($A6="","",COUNTIFS(Assignments!$B$6:$B$305,$A6,Assignments!$D$6:$D$305,">="&Config!$B$3-7,Assignments!$D$6:$D$305,"<="&Config!$B$3)) -> 0 | G6: =IF($A6="","",MAXIFS(Assignments!$D$6:$D$305,Assignments!$B$6:$B$305,$A6)) -> 0 | H6: =IF($A6="","",IF($G6="","",Config!$B$3-$G6)) -> 46071 | I6: =IF($A6="","",IF($D6=0,"",$E6/$D6)) -> 0 | J6: =IF($A6="","",IFERROR(AVERAGEIFS(Assignments!$N$6:$N$1000,Assignments!$B$6:$B$1000,$A6,Assignments!$E$6:$E$1000,"Completed"),"")) | K6: =IF($A6="","",IFERROR(AVERAGEIFS(Assignments!$AO:$AO,Assignments!$B:$B,$A6,Assignments!$E:$E,"Completed"),"")) | L6: =IF($A6="","",IFERROR(COUNTIFS(Assignments!$B$6:$B$1000,$A6,Assignments!$E$6:$E$1000,"Cancelled")/MAX(1,COUNTIFS(Assignments!$B$6:$B$1000,$A6,Assignments!$E$6:$E$1000,"Completed")+COUNTIFS(Assignments!$B$6:$B$1000,$A6,Assignments!$E$6:$E$1000,"Cancelled")),"")) -> 0 | M6: =IF($A6="","",IFERROR(AVERAGEIFS(Assignments!$P$6:$P$1000,Assignments!$B$6:$B$1000,$A6,Assignments!$E$6:$E$1000,"Completed"),"")) | N6: - | P6: =IF(A6="","",MAX(0,MIN(3,SUMIFS(Strike_Log!$C:$C,Strike_Log!$B:$B,A6,Strike_Log!$A:$A,">="&IF(Config!$B$1004="Y",TODAY()-Config!$B$1005,DATE(1900,1,1)),Strike_Log!$I:$I,1)))) -> 0 | Q6: =IF(P6="",0,CHOOSE(MIN(3,MAX(0,P6))+1,0,0.03,0.07,0.2)) -> 0 | R6: =IF(A6="","",IFERROR(AVERAGEIFS(Assignments!$J:$J,Assignments!$B:$B,A6,Assignments!$E:$E,"Completed"),"")) | S6: =IF(A6="","",COUNTIFS(Assignments!$B:$B,A6,Assignments!$AE:$AE, "Y",Assignments!$D:$D,">="&TODAY()-30)) -> 0 | T6: =IF(A6="","",COUNTIFS(Assignments!$AF:$AF,A6,Assignments!$AE:$AE, "Y",Assignments!$D:$D,">="&TODAY()-30)) -> 0 | U6: =IF(A6="","",IFERROR(S6/MAX(1,COUNTIFS(Assignments!$B:$B,A6,Assignments!$D:$D,">="&TODAY()-30)),"")) -> 0 | V6: =IF(A6="","",T6-S6) -> 0
A7: GRD-04 | B7: andydpoy | C7: Regular | D7: =IF($C7="Regular","3","5") -> 3 | E7: =IF($A7="","",COUNTIFS(Assignments!$B$6:$B$305,$A7,Assignments!$E$6:$E$305,"Active")) -> 0 | F7: =IF($A7="","",COUNTIFS(Assignments!$B$6:$B$305,$A7,Assignments!$D$6:$D$305,">="&Config!$B$3-7,Assignments!$D$6:$D$305,"<="&Config!$B$3)) -> 0 | G7: =IF($A7="","",MAXIFS(Assignments!$D$6:$D$305,Assignments!$B$6:$B$305,$A7)) -> 0 | H7: =IF($A7="","",IF($G7="","",Config!$B$3-$G7)) -> 46071 | I7: =IF($A7="","",IF($D7=0,"",$E7/$D7)) -> 0 | J7: =IF($A7="","",IFERROR(AVERAGEIFS(Assignments!$N$6:$N$1000,Assignments!$B$6:$B$1000,$A7,Assignments!$E$6:$E$1000,"Completed"),"")) | K7: =IF($A7="","",IFERROR(AVERAGEIFS(Assignments!$AO:$AO,Assignments!$B:$B,$A7,Assignments!$E:$E,"Completed"),"")) | L7: =IF($A7="","",IFERROR(COUNTIFS(Assignments!$B$6:$B$1000,$A7,Assignments!$E$6:$E$1000,"Cancelled")/MAX(1,COUNTIFS(Assignments!$B$6:$B$1000,$A7,Assignments!$E$6:$E$1000,"Completed")+COUNTIFS(Assignments!$B$6:$B$1000,$A7,Assignments!$E$6:$E$1000,"Cancelled")),"")) -> 0 | M7: =IF($A7="","",IFERROR(AVERAGEIFS(Assignments!$P$6:$P$1000,Assignments!$B$6:$B$1000,$A7,Assignments!$E$6:$E$1000,"Completed"),"")) | N7: - | P7: =IF(A7="","",MAX(0,MIN(3,SUMIFS(Strike_Log!$C:$C,Strike_Log!$B:$B,A7,Strike_Log!$A:$A,">="&IF(Config!$B$1004="Y",TODAY()-Config!$B$1005,DATE(1900,1,1)),Strike_Log!$I:$I,1)))) -> 0 | Q7: =IF(P7="",0,CHOOSE(MIN(3,MAX(0,P7))+1,0,0.03,0.07,0.2)) -> 0 | R7: =IF(A7="","",IFERROR(AVERAGEIFS(Assignments!$J:$J,Assignments!$B:$B,A7,Assignments!$E:$E,"Completed"),"")) | S7: =IF(A7="","",COUNTIFS(Assignments!$B:$B,A7,Assignments!$AE:$AE, "Y",Assignments!$D:$D,">="&TODAY()-30)) -> 0 | T7: =IF(A7="","",COUNTIFS(Assignments!$AF:$AF,A7,Assignments!$AE:$AE, "Y",Assignments!$D:$D,">="&TODAY()-30)) -> 0 | U7: =IF(A7="","",IFERROR(S7/MAX(1,COUNTIFS(Assignments!$B:$B,A7,Assignments!$D:$D,">="&TODAY()-30)),"")) -> 0 | V7: =IF(A7="","",T7-S7) -> 0
A8: GRD-05 | B8: anklesreborn | C8: Regular | D8: =IF($C8="Regular","3","5") -> 3 | E8: =IF($A8="","",COUNTIFS(Assignments!$B$6:$B$305,$A8,Assignments!$E$6:$E$305,"Active")) -> 0 | F8: =IF($A8="","",COUNTIFS(Assignments!$B$6:$B$305,$A8,Assignments!$D$6:$D$305,">="&Config!$B$3-7,Assignments!$D$6:$D$305,"<="&Config!$B$3)) -> 0 | G8: =IF($A8="","",MAXIFS(Assignments!$D$6:$D$305,Assignments!$B$6:$B$305,$A8)) -> 0 | H8: =IF($A8="","",IF($G8="","",Config!$B$3-$G8)) -> 46071 | I8: =IF($A8="","",IF($D8=0,"",$E8/$D8)) -> 0 | J8: =IF($A8="","",IFERROR(AVERAGEIFS(Assignments!$N$6:$N$1000,Assignments!$B$6:$B$1000,$A8,Assignments!$E$6:$E$1000,"Completed"),"")) | K8: =IF($A8="","",IFERROR(AVERAGEIFS(Assignments!$AO:$AO,Assignments!$B:$B,$A8,Assignments!$E:$E,"Completed"),"")) | L8: =IF($A8="","",IFERROR(COUNTIFS(Assignments!$B$6:$B$1000,$A8,Assignments!$E$6:$E$1000,"Cancelled")/MAX(1,COUNTIFS(Assignments!$B$6:$B$1000,$A8,Assignments!$E$6:$E$1000,"Completed")+COUNTIFS(Assignments!$B$6:$B$1000,$A8,Assignments!$E$6:$E$1000,"Cancelled")),"")) -> 0 | M8: =IF($A8="","",IFERROR(AVERAGEIFS(Assignments!$P$6:$P$1000,Assignments!$B$6:$B$1000,$A8,Assignments!$E$6:$E$1000,"Completed"),"")) | N8: - | P8: =IF(A8="","",MAX(0,MIN(3,SUMIFS(Strike_Log!$C:$C,Strike_Log!$B:$B,A8,Strike_Log!$A:$A,">="&IF(Config!$B$1004="Y",TODAY()-Config!$B$1005,DATE(1900,1,1)),Strike_Log!$I:$I,1)))) -> 0 | Q8: =IF(P8="",0,CHOOSE(MIN(3,MAX(0,P8))+1,0,0.03,0.07,0.2)) -> 0 | R8: =IF(A8="","",IFERROR(AVERAGEIFS(Assignments!$J:$J,Assignments!$B:$B,A8,Assignments!$E:$E,"Completed"),"")) | S8: =IF(A8="","",COUNTIFS(Assignments!$B:$B,A8,Assignments!$AE:$AE, "Y",Assignments!$D:$D,">="&TODAY()-30)) -> 0 | T8: =IF(A8="","",COUNTIFS(Assignments!$AF:$AF,A8,Assignments!$AE:$AE, "Y",Assignments!$D:$D,">="&TODAY()-30)) -> 0 | U8: =IF(A8="","",IFERROR(S8/MAX(1,COUNTIFS(Assignments!$B:$B,A8,Assignments!$D:$D,">="&TODAY()-30)),"")) -> 0 | V8: =IF(A8="","",T8-S8) -> 0
A9: GRD-06 | B9: ant0513 | C9: Regular | D9: =IF($C9="Regular","3","5") -> 3 | E9: =IF($A9="","",COUNTIFS(Assignments!$B$6:$B$305,$A9,Assignments!$E$6:$E$305,"Active")) -> 0 | F9: =IF($A9="","",COUNTIFS(Assignments!$B$6:$B$305,$A9,Assignments!$D$6:$D$305,">="&Config!$B$3-7,Assignments!$D$6:$D$305,"<="&Config!$B$3)) -> 0 | G9: =IF($A9="","",MAXIFS(Assignments!$D$6:$D$305,Assignments!$B$6:$B$305,$A9)) -> 0 | H9: =IF($A9="","",IF($G9="","",Config!$B$3-$G9)) -> 46071 | I9: =IF($A9="","",IF($D9=0,"",$E9/$D9)) -> 0 | J9: =IF($A9="","",IFERROR(AVERAGEIFS(Assignments!$N$6:$N$1000,Assignments!$B$6:$B$1000,$A9,Assignments!$E$6:$E$1000,"Completed"),"")) | K9: =IF($A9="","",IFERROR(AVERAGEIFS(Assignments!$AO:$AO,Assignments!$B:$B,$A9,Assignments!$E:$E,"Completed"),"")) | L9: =IF($A9="","",IFERROR(COUNTIFS(Assignments!$B$6:$B$1000,$A9,Assignments!$E$6:$E$1000,"Cancelled")/MAX(1,COUNTIFS(Assignments!$B$6:$B$1000,$A9,Assignments!$E$6:$E$1000,"Completed")+COUNTIFS(Assignments!$B$6:$B$1000,$A9,Assignments!$E$6:$E$1000,"Cancelled")),"")) -> 0 | M9: =IF($A9="","",IFERROR(AVERAGEIFS(Assignments!$P$6:$P$1000,Assignments!$B$6:$B$1000,$A9,Assignments!$E$6:$E$1000,"Completed"),"")) | N9: - | P9: =IF(A9="","",MAX(0,MIN(3,SUMIFS(Strike_Log!$C:$C,Strike_Log!$B:$B,A9,Strike_Log!$A:$A,">="&IF(Config!$B$1004="Y",TODAY()-Config!$B$1005,DATE(1900,1,1)),Strike_Log!$I:$I,1)))) -> 0 | Q9: =IF(P9="",0,CHOOSE(MIN(3,MAX(0,P9))+1,0,0.03,0.07,0.2)) -> 0 | R9: =IF(A9="","",IFERROR(AVERAGEIFS(Assignments!$J:$J,Assignments!$B:$B,A9,Assignments!$E:$E,"Completed"),"")) | S9: =IF(A9="","",COUNTIFS(Assignments!$B:$B,A9,Assignments!$AE:$AE, "Y",Assignments!$D:$D,">="&TODAY()-30)) -> 0 | T9: =IF(A9="","",COUNTIFS(Assignments!$AF:$AF,A9,Assignments!$AE:$AE, "Y",Assignments!$D:$D,">="&TODAY()-30)) -> 0 | U9: =IF(A9="","",IFERROR(S9/MAX(1,COUNTIFS(Assignments!$B:$B,A9,Assignments!$D:$D,">="&TODAY()-30)),"")) -> 0 | V9: =IF(A9="","",T9-S9) -> 0
A10: GRD-07 | B10: asierxx | C10: Regular | D10: =IF($C10="Regular","3","5") -> 3 | E10: =IF($A10="","",COUNTIFS(Assignments!$B$6:$B$305,$A10,Assignments!$E$6:$E$305,"Active")) -> 0 | F10: =IF($A10="","",COUNTIFS(Assignments!$B$6:$B$305,$A10,Assignments!$D$6:$D$305,">="&Config!$B$3-7,Assignments!$D$6:$D$305,"<="&Config!$B$3)) -> 0 | G10: =IF($A10="","",MAXIFS(Assignments!$D$6:$D$305,Assignments!$B$6:$B$305,$A10)) -> 0 | H10: =IF($A10="","",IF($G10="","",Config!$B$3-$G10)) -> 46071 | I10: =IF($A10="","",IF($D10=0,"",$E10/$D10)) -> 0 | J10: =IF($A10="","",IFERROR(AVERAGEIFS(Assignments!$N$6:$N$1000,Assignments!$B$6:$B$1000,$A10,Assignments!$E$6:$E$1000,"Completed"),"")) | K10: =IF($A10="","",IFERROR(AVERAGEIFS(Assignments!$AO:$AO,Assignments!$B:$B,$A10,Assignments!$E:$E,"Completed"),"")) | L10: =IF($A10="","",IFERROR(COUNTIFS(Assignments!$B$6:$B$1000,$A10,Assignments!$E$6:$E$1000,"Cancelled")/MAX(1,COUNTIFS(Assignments!$B$6:$B$1000,$A10,Assignments!$E$6:$E$1000,"Completed")+COUNTIFS(Assignments!$B$6:$B$1000,$A10,Assignments!$E$6:$E$1000,"Cancelled")),"")) -> 0 | M10: =IF($A10="","",IFERROR(AVERAGEIFS(Assignments!$P$6:$P$1000,Assignments!$B$6:$B$1000,$A10,Assignments!$E$6:$E$1000,"Completed"),"")) | N10: - | P10: =IF(A10="","",MAX(0,MIN(3,SUMIFS(Strike_Log!$C:$C,Strike_Log!$B:$B,A10,Strike_Log!$A:$A,">="&IF(Config!$B$1004="Y",TODAY()-Config!$B$1005,DATE(1900,1,1)),Strike_Log!$I:$I,1)))) -> 0 | Q10: =IF(P10="",0,CHOOSE(MIN(3,MAX(0,P10))+1,0,0.03,0.07,0.2)) -> 0 | R10: =IF(A10="","",IFERROR(AVERAGEIFS(Assignments!$J:$J,Assignments!$B:$B,A10,Assignments!$E:$E,"Completed"),"")) | S10: =IF(A10="","",COUNTIFS(Assignments!$B:$B,A10,Assignments!$AE:$AE, "Y",Assignments!$D:$D,">="&TODAY()-30)) -> 0 | T10: =IF(A10="","",COUNTIFS(Assignments!$AF:$AF,A10,Assignments!$AE:$AE, "Y",Assignments!$D:$D,">="&TODAY()-30)) -> 0 | U10: =IF(A10="","",IFERROR(S10/MAX(1,COUNTIFS(Assignments!$B:$B,A10,Assignments!$D:$D,">="&TODAY()-30)),"")) -> 0 | V10: =IF(A10="","",T10-S10) -> 0
A11: GRD-08 | B11: bigt20011_ | C11: Regular | D11: =IF($C11="Regular","3","5") -> 3 | E11: =IF($A11="","",COUNTIFS(Assignments!$B$6:$B$305,$A11,Assignments!$E$6:$E$305,"Active")) -> 0 | F11: =IF($A11="","",COUNTIFS(Assignments!$B$6:$B$305,$A11,Assignments!$D$6:$D$305,">="&Config!$B$3-7,Assignments!$D$6:$D$305,"<="&Config!$B$3)) -> 0 | G11: =IF($A11="","",MAXIFS(Assignments!$D$6:$D$305,Assignments!$B$6:$B$305,$A11)) -> 0 | H11: =IF($A11="","",IF($G11="","",Config!$B$3-$G11)) -> 46071 | I11: =IF($A11="","",IF($D11=0,"",$E11/$D11)) -> 0 | J11: =IF($A11="","",IFERROR(AVERAGEIFS(Assignments!$N$6:$N$1000,Assignments!$B$6:$B$1000,$A11,Assignments!$E$6:$E$1000,"Completed"),"")) | K11: =IF($A11="","",IFERROR(AVERAGEIFS(Assignments!$AO:$AO,Assignments!$B:$B,$A11,Assignments!$E:$E,"Completed"),"")) | L11: =IF($A11="","",IFERROR(COUNTIFS(Assignments!$B$6:$B$1000,$A11,Assignments!$E$6:$E$1000,"Cancelled")/MAX(1,COUNTIFS(Assignments!$B$6:$B$1000,$A11,Assignments!$E$6:$E$1000,"Completed")+COUNTIFS(Assignments!$B$6:$B$1000,$A11,Assignments!$E$6:$E$1000,"Cancelled")),"")) -> 0 | M11: =IF($A11="","",IFERROR(AVERAGEIFS(Assignments!$P$6:$P$1000,Assignments!$B$6:$B$1000,$A11,Assignments!$E$6:$E$1000,"Completed"),"")) | N11: - | P11: =IF(A11="","",MAX(0,MIN(3,SUMIFS(Strike_Log!$C:$C,Strike_Log!$B:$B,A11,Strike_Log!$A:$A,">="&IF(Config!$B$1004="Y",TODAY()-Config!$B$1005,DATE(1900,1,1)),Strike_Log!$I:$I,1)))) -> 0 | Q11: =IF(P11="",0,CHOOSE(MIN(3,MAX(0,P11))+1,0,0.03,0.07,0.2)) -> 0 | R11: =IF(A11="","",IFERROR(AVERAGEIFS(Assignments!$J:$J,Assignments!$B:$B,A11,Assignments!$E:$E,"Completed"),"")) | S11: =IF(A11="","",COUNTIFS(Assignments!$B:$B,A11,Assignments!$AE:$AE, "Y",Assignments!$D:$D,">="&TODAY()-30)) -> 0 | T11: =IF(A11="","",COUNTIFS(Assignments!$AF:$AF,A11,Assignments!$AE:$AE, "Y",Assignments!$D:$D,">="&TODAY()-30)) -> 0 | U11: =IF(A11="","",IFERROR(S11/MAX(1,COUNTIFS(Assignments!$B:$B,A11,Assignments!$D:$D,">="&TODAY()-30)),"")) -> 0 | V11: =IF(A11="","",T11-S11) -> 0
A12: GRD-09 | B12: boards4238 | C12: Regular | D12: =IF($C12="Regular","3","5") -> 3 | E12: =IF($A12="","",COUNTIFS(Assignments!$B$6:$B$305,$A12,Assignments!$E$6:$E$305,"Active")) -> 0 | F12: =IF($A12="","",COUNTIFS(Assignments!$B$6:$B$305,$A12,Assignments!$D$6:$D$305,">="&Config!$B$3-7,Assignments!$D$6:$D$305,"<="&Config!$B$3)) -> 0 | G12: =IF($A12="","",MAXIFS(Assignments!$D$6:$D$305,Assignments!$B$6:$B$305,$A12)) -> 0 | H12: =IF($A12="","",IF($G12="","",Config!$B$3-$G12)) -> 46071 | I12: =IF($A12="","",IF($D12=0,"",$E12/$D12)) -> 0 | J12: =IF($A12="","",IFERROR(AVERAGEIFS(Assignments!$N$6:$N$1000,Assignments!$B$6:$B$1000,$A12,Assignments!$E$6:$E$1000,"Completed"),"")) | K12: =IF($A12="","",IFERROR(AVERAGEIFS(Assignments!$AO:$AO,Assignments!$B:$B,$A12,Assignments!$E:$E,"Completed"),"")) | L12: =IF($A12="","",IFERROR(COUNTIFS(Assignments!$B$6:$B$1000,$A12,Assignments!$E$6:$E$1000,"Cancelled")/MAX(1,COUNTIFS(Assignments!$B$6:$B$1000,$A12,Assignments!$E$6:$E$1000,"Completed")+COUNTIFS(Assignments!$B$6:$B$1000,$A12,Assignments!$E$6:$E$1000,"Cancelled")),"")) -> 0 | M12: =IF($A12="","",IFERROR(AVERAGEIFS(Assignments!$P$6:$P$1000,Assignments!$B$6:$B$1000,$A12,Assignments!$E$6:$E$1000,"Completed"),"")) | N12: - | P12: =IF(A12="","",MAX(0,MIN(3,SUMIFS(Strike_Log!$C:$C,Strike_Log!$B:$B,A12,Strike_Log!$A:$A,">="&IF(Config!$B$1004="Y",TODAY()-Config!$B$1005,DATE(1900,1,1)),Strike_Log!$I:$I,1)))) -> 0 | Q12: =IF(P12="",0,CHOOSE(MIN(3,MAX(0,P12))+1,0,0.03,0.07,0.2)) -> 0 | R12: =IF(A12="","",IFERROR(AVERAGEIFS(Assignments!$J:$J,Assignments!$B:$B,A12,Assignments!$E:$E,"Completed"),"")) | S12: =IF(A12="","",COUNTIFS(Assignments!$B:$B,A12,Assignments!$AE:$AE, "Y",Assignments!$D:$D,">="&TODAY()-30)) -> 0 | T12: =IF(A12="","",COUNTIFS(Assignments!$AF:$AF,A12,Assignments!$AE:$AE, "Y",Assignments!$D:$D,">="&TODAY()-30)) -> 0 | U12: =IF(A12="","",IFERROR(S12/MAX(1,COUNTIFS(Assignments!$B:$B,A12,Assignments!$D:$D,">="&TODAY()-30)),"")) -> 0 | V12: =IF(A12="","",T12-S12) -> 0
A13: GRD-10 | B13: bumped240hz | C13: Regular | D13: =IF($C13="Regular","3","5") -> 3 | E13: =IF($A13="","",COUNTIFS(Assignments!$B$6:$B$305,$A13,Assignments!$E$6:$E$305,"Active")) -> 0 | F13: =IF($A13="","",COUNTIFS(Assignments!$B$6:$B$305,$A13,Assignments!$D$6:$D$305,">="&Config!$B$3-7,Assignments!$D$6:$D$305,"<="&Config!$B$3)) -> 0 | G13: =IF($A13="","",MAXIFS(Assignments!$D$6:$D$305,Assignments!$B$6:$B$305,$A13)) -> 0 | H13: =IF($A13="","",IF($G13="","",Config!$B$3-$G13)) -> 46071 | I13: =IF($A13="","",IF($D13=0,"",$E13/$D13)) -> 0 | J13: =IF($A13="","",IFERROR(AVERAGEIFS(Assignments!$N$6:$N$1000,Assignments!$B$6:$B$1000,$A13,Assignments!$E$6:$E$1000,"Completed"),"")) | K13: =IF($A13="","",IFERROR(AVERAGEIFS(Assignments!$AO:$AO,Assignments!$B:$B,$A13,Assignments!$E:$E,"Completed"),"")) | L13: =IF($A13="","",IFERROR(COUNTIFS(Assignments!$B$6:$B$1000,$A13,Assignments!$E$6:$E$1000,"Cancelled")/MAX(1,COUNTIFS(Assignments!$B$6:$B$1000,$A13,Assignments!$E$6:$E$1000,"Completed")+COUNTIFS(Assignments!$B$6:$B$1000,$A13,Assignments!$E$6:$E$1000,"Cancelled")),"")) -> 0 | M13: =IF($A13="","",IFERROR(AVERAGEIFS(Assignments!$P$6:$P$1000,Assignments!$B$6:$B$1000,$A13,Assignments!$E$6:$E$1000,"Completed"),"")) | N13: - | P13: =IF(A13="","",MAX(0,MIN(3,SUMIFS(Strike_Log!$C:$C,Strike_Log!$B:$B,A13,Strike_Log!$A:$A,">="&IF(Config!$B$1004="Y",TODAY()-Config!$B$1005,DATE(1900,1,1)),Strike_Log!$I:$I,1)))) -> 0 | Q13: =IF(P13="",0,CHOOSE(MIN(3,MAX(0,P13))+1,0,0.03,0.07,0.2)) -> 0 | R13: =IF(A13="","",IFERROR(AVERAGEIFS(Assignments!$J:$J,Assignments!$B:$B,A13,Assignments!$E:$E,"Completed"),"")) | S13: =IF(A13="","",COUNTIFS(Assignments!$B:$B,A13,Assignments!$AE:$AE, "Y",Assignments!$D:$D,">="&TODAY()-30)) -> 0 | T13: =IF(A13="","",COUNTIFS(Assignments!$AF:$AF,A13,Assignments!$AE:$AE, "Y",Assignments!$D:$D,">="&TODAY()-30)) -> 0 | U13: =IF(A13="","",IFERROR(S13/MAX(1,COUNTIFS(Assignments!$B:$B,A13,Assignments!$D:$D,">="&TODAY()-30)),"")) -> 0 | V13: =IF(A13="","",T13-S13) -> 0
A14: GRD-11 | B14: bumpincombos | C14: Regular | D14: =IF($C14="Regular","3","5") -> 3 | E14: =IF($A14="","",COUNTIFS(Assignments!$B$6:$B$305,$A14,Assignments!$E$6:$E$305,"Active")) -> 0 | F14: =IF($A14="","",COUNTIFS(Assignments!$B$6:$B$305,$A14,Assignments!$D$6:$D$305,">="&Config!$B$3-7,Assignments!$D$6:$D$305,"<="&Config!$B$3)) -> 0 | G14: =IF($A14="","",MAXIFS(Assignments!$D$6:$D$305,Assignments!$B$6:$B$305,$A14)) -> 0 | H14: =IF($A14="","",IF($G14="","",Config!$B$3-$G14)) -> 46071 | I14: =IF($A14="","",IF($D14=0,"",$E14/$D14)) -> 0 | J14: =IF($A14="","",IFERROR(AVERAGEIFS(Assignments!$N$6:$N$1000,Assignments!$B$6:$B$1000,$A14,Assignments!$E$6:$E$1000,"Completed"),"")) | K14: =IF($A14="","",IFERROR(AVERAGEIFS(Assignments!$AO:$AO,Assignments!$B:$B,$A14,Assignments!$E:$E,"Completed"),"")) | L14: =IF($A14="","",IFERROR(COUNTIFS(Assignments!$B$6:$B$1000,$A14,Assignments!$E$6:$E$1000,"Cancelled")/MAX(1,COUNTIFS(Assignments!$B$6:$B$1000,$A14,Assignments!$E$6:$E$1000,"Completed")+COUNTIFS(Assignments!$B$6:$B$1000,$A14,Assignments!$E$6:$E$1000,"Cancelled")),"")) -> 0 | M14: =IF($A14="","",IFERROR(AVERAGEIFS(Assignments!$P$6:$P$1000,Assignments!$B$6:$B$1000,$A14,Assignments!$E$6:$E$1000,"Completed"),"")) | N14: - | P14: =IF(A14="","",MAX(0,MIN(3,SUMIFS(Strike_Log!$C:$C,Strike_Log!$B:$B,A14,Strike_Log!$A:$A,">="&IF(Config!$B$1004="Y",TODAY()-Config!$B$1005,DATE(1900,1,1)),Strike_Log!$I:$I,1)))) -> 0 | Q14: =IF(P14="",0,CHOOSE(MIN(3,MAX(0,P14))+1,0,0.03,0.07,0.2)) -> 0 | R14: =IF(A14="","",IFERROR(AVERAGEIFS(Assignments!$J:$J,Assignments!$B:$B,A14,Assignments!$E:$E,"Completed"),"")) | S14: =IF(A14="","",COUNTIFS(Assignments!$B:$B,A14,Assignments!$AE:$AE, "Y",Assignments!$D:$D,">="&TODAY()-30)) -> 0 | T14: =IF(A14="","",COUNTIFS(Assignments!$AF:$AF,A14,Assignments!$AE:$AE, "Y",Assignments!$D:$D,">="&TODAY()-30)) -> 0 | U14: =IF(A14="","",IFERROR(S14/MAX(1,COUNTIFS(Assignments!$B:$B,A14,Assignments!$D:$D,">="&TODAY()-30)),"")) -> 0 | V14: =IF(A14="","",T14-S14) -> 0
A15: GRD-12 | B15: cerhzn | C15: Regular | D15: =IF($C15="Regular","3","5") -> 3 | E15: =IF($A15="","",COUNTIFS(Assignments!$B$6:$B$305,$A15,Assignments!$E$6:$E$305,"Active")) -> 0 | F15: =IF($A15="","",COUNTIFS(Assignments!$B$6:$B$305,$A15,Assignments!$D$6:$D$305,">="&Config!$B$3-7,Assignments!$D$6:$D$305,"<="&Config!$B$3)) -> 0 | G15: =IF($A15="","",MAXIFS(Assignments!$D$6:$D$305,Assignments!$B$6:$B$305,$A15)) -> 0 | H15: =IF($A15="","",IF($G15="","",Config!$B$3-$G15)) -> 46071 | I15: =IF($A15="","",IF($D15=0,"",$E15/$D15)) -> 0 | J15: =IF($A15="","",IFERROR(AVERAGEIFS(Assignments!$N$6:$N$1000,Assignments!$B$6:$B$1000,$A15,Assignments!$E$6:$E$1000,"Completed"),"")) | K15: =IF($A15="","",IFERROR(AVERAGEIFS(Assignments!$AO:$AO,Assignments!$B:$B,$A15,Assignments!$E:$E,"Completed"),"")) | L15: =IF($A15="","",IFERROR(COUNTIFS(Assignments!$B$6:$B$1000,$A15,Assignments!$E$6:$E$1000,"Cancelled")/MAX(1,COUNTIFS(Assignments!$B$6:$B$1000,$A15,Assignments!$E$6:$E$1000,"Completed")+COUNTIFS(Assignments!$B$6:$B$1000,$A15,Assignments!$E$6:$E$1000,"Cancelled")),"")) -> 0 | M15: =IF($A15="","",IFERROR(AVERAGEIFS(Assignments!$P$6:$P$1000,Assignments!$B$6:$B$1000,$A15,Assignments!$E$6:$E$1000,"Completed"),"")) | N15: - | P15: =IF(A15="","",MAX(0,MIN(3,SUMIFS(Strike_Log!$C:$C,Strike_Log!$B:$B,A15,Strike_Log!$A:$A,">="&IF(Config!$B$1004="Y",TODAY()-Config!$B$1005,DATE(1900,1,1)),Strike_Log!$I:$I,1)))) -> 0 | Q15: =IF(P15="",0,CHOOSE(MIN(3,MAX(0,P15))+1,0,0.03,0.07,0.2)) -> 0 | R15: =IF(A15="","",IFERROR(AVERAGEIFS(Assignments!$J:$J,Assignments!$B:$B,A15,Assignments!$E:$E,"Completed"),"")) | S15: =IF(A15="","",COUNTIFS(Assignments!$B:$B,A15,Assignments!$AE:$AE, "Y",Assignments!$D:$D,">="&TODAY()-30)) -> 0 | T15: =IF(A15="","",COUNTIFS(Assignments!$AF:$AF,A15,Assignments!$AE:$AE, "Y",Assignments!$D:$D,">="&TODAY()-30)) -> 0 | U15: =IF(A15="","",IFERROR(S15/MAX(1,COUNTIFS(Assignments!$B:$B,A15,Assignments!$D:$D,">="&TODAY()-30)),"")) -> 0 | V15: =IF(A15="","",T15-S15) -> 0
A16: GRD-13 | B16: comptomuch | C16: Elite | D16: =IF($C16="Regular","3","5") -> 5 | E16: =IF($A16="","",COUNTIFS(Assignments!$B$6:$B$305,$A16,Assignments!$E$6:$E$305,"Active")) -> 0 | F16: =IF($A16="","",COUNTIFS(Assignments!$B$6:$B$305,$A16,Assignments!$D$6:$D$305,">="&Config!$B$3-7,Assignments!$D$6:$D$305,"<="&Config!$B$3)) -> 0 | G16: =IF($A16="","",MAXIFS(Assignments!$D$6:$D$305,Assignments!$B$6:$B$305,$A16)) -> 0 | H16: =IF($A16="","",IF($G16="","",Config!$B$3-$G16)) -> 46071 | I16: =IF($A16="","",IF($D16=0,"",$E16/$D16)) -> 0 | J16: =IF($A16="","",IFERROR(AVERAGEIFS(Assignments!$N$6:$N$1000,Assignments!$B$6:$B$1000,$A16,Assignments!$E$6:$E$1000,"Completed"),"")) | K16: =IF($A16="","",IFERROR(AVERAGEIFS(Assignments!$AO:$AO,Assignments!$B:$B,$A16,Assignments!$E:$E,"Completed"),"")) | L16: =IF($A16="","",IFERROR(COUNTIFS(Assignments!$B$6:$B$1000,$A16,Assignments!$E$6:$E$1000,"Cancelled")/MAX(1,COUNTIFS(Assignments!$B$6:$B$1000,$A16,Assignments!$E$6:$E$1000,"Completed")+COUNTIFS(Assignments!$B$6:$B$1000,$A16,Assignments!$E$6:$E$1000,"Cancelled")),"")) -> 0 | M16: =IF($A16="","",IFERROR(AVERAGEIFS(Assignments!$P$6:$P$1000,Assignments!$B$6:$B$1000,$A16,Assignments!$E$6:$E$1000,"Completed"),"")) | N16: - | P16: =IF(A16="","",MAX(0,MIN(3,SUMIFS(Strike_Log!$C:$C,Strike_Log!$B:$B,A16,Strike_Log!$A:$A,">="&IF(Config!$B$1004="Y",TODAY()-Config!$B$1005,DATE(1900,1,1)),Strike_Log!$I:$I,1)))) -> 0 | Q16: =IF(P16="",0,CHOOSE(MIN(3,MAX(0,P16))+1,0,0.03,0.07,0.2)) -> 0 | R16: =IF(A16="","",IFERROR(AVERAGEIFS(Assignments!$J:$J,Assignments!$B:$B,A16,Assignments!$E:$E,"Completed"),"")) | S16: =IF(A16="","",COUNTIFS(Assignments!$B:$B,A16,Assignments!$AE:$AE, "Y",Assignments!$D:$D,">="&TODAY()-30)) -> 0 | T16: =IF(A16="","",COUNTIFS(Assignments!$AF:$AF,A16,Assignments!$AE:$AE, "Y",Assignments!$D:$D,">="&TODAY()-30)) -> 0 | U16: =IF(A16="","",IFERROR(S16/MAX(1,COUNTIFS(Assignments!$B:$B,A16,Assignments!$D:$D,">="&TODAY()-30)),"")) -> 0 | V16: =IF(A16="","",T16-S16) -> 0
... A37: GRD-34 | B37: jitxx | C37: Regular | D37: =IF($C37="Regular","3","5") -> 3 | E37: =IF($A37="","",COUNTIFS(Assignments!$B$6:$B$305,$A37,Assignments!$E$6:$E$305,"Active")) -> 0 | F37: =IF($A37="","",COUNTIFS(Assignments!$B$6:$B$305,$A37,Assignments!$D$6:$D$305,">="&Config!$B$3-7,Assignments!$D$6:$D$305,"<="&Config!$B$3)) -> 0 | G37: =IF($A37="","",MAXIFS(Assignments!$D$6:$D$305,Assignments!$B$6:$B$305,$A37)) -> 0 | H37: =IF($A37="","",IF($G37="","",Config!$B$3-$G37)) -> 46071 | I37: =IF($A37="","",IF($D37=0,"",$E37/$D37)) -> 0 | J37: =IF($A37="","",IFERROR(AVERAGEIFS(Assignments!$N$6:$N$1000,Assignments!$B$6:$B$1000,$A37,Assignments!$E$6:$E$1000,"Completed"),"")) | K37: =IF($A37="","",IFERROR(AVERAGEIFS(Assignments!$AO:$AO,Assignments!$B:$B,$A37,Assignments!$E:$E,"Completed"),"")) | L37: =IF($A37="","",IFERROR(COUNTIFS(Assignments!$B$6:$B$1000,$A37,Assignments!$E$6:$E$1000,"Cancelled")/MAX(1,COUNTIFS(Assignments!$B$6:$B$1000,$A37,Assignments!$E$6:$E$1000,"Completed")+COUNTIFS(Assignments!$B$6:$B$1000,$A37,Assignments!$E$6:$E$1000,"Cancelled")),"")) -> 0 | M37: =IF($A37="","",IFERROR(AVERAGEIFS(Assignments!$P$6:$P$1000,Assignments!$B$6:$B$1000,$A37,Assignments!$E$6:$E$1000,"Completed"),"")) | N37: - | P37: =IF(A37="","",MAX(0,MIN(3,SUMIFS(Strike_Log!$C:$C,Strike_Log!$B:$B,A37,Strike_Log!$A:$A,">="&IF(Config!$B$1004="Y",TODAY()-Config!$B$1005,DATE(1900,1,1)),Strike_Log!$I:$I,1)))) -> 0 | Q37: =IF(P37="",0,CHOOSE(MIN(3,MAX(0,P37))+1,0,0.03,0.07,0.2)) -> 0 | R37: =IF(A37="","",IFERROR(AVERAGEIFS(Assignments!$J:$J,Assignments!$B:$B,A37,Assignments!$E:$E,"Completed"),"")) | S37: =IF(A37="","",COUNTIFS(Assignments!$B:$B,A37,Assignments!$AE:$AE, "Y",Assignments!$D:$D,">="&TODAY()-30)) -> 0 | T37: =IF(A37="","",COUNTIFS(Assignments!$AF:$AF,A37,Assignments!$AE:$AE, "Y",Assignments!$D:$D,">="&TODAY()-30)) -> 0 | U37: =IF(A37="","",IFERROR(S37/MAX(1,COUNTIFS(Assignments!$B:$B,A37,Assignments!$D:$D,">="&TODAY()-30)),"")) -> 0 | V37: =IF(A37="","",T37-S37) -> 0
A38: GRD-35 | B38: 768288 | C38: Regular | D38: =IF($C38="Regular","3","5") -> 3 | E38: =IF($A38="","",COUNTIFS(Assignments!$B$6:$B$305,$A38,Assignments!$E$6:$E$305,"Active")) -> 0 | F38: =IF($A38="","",COUNTIFS(Assignments!$B$6:$B$305,$A38,Assignments!$D$6:$D$305,">="&Config!$B$3-7,Assignments!$D$6:$D$305,"<="&Config!$B$3)) -> 0 | G38: =IF($A38="","",MAXIFS(Assignments!$D$6:$D$305,Assignments!$B$6:$B$305,$A38)) -> 0 | H38: =IF($A38="","",IF($G38="","",Config!$B$3-$G38)) -> 46071 | I38: =IF($A38="","",IF($D38=0,"",$E38/$D38)) -> 0 | J38: =IF($A38="","",IFERROR(AVERAGEIFS(Assignments!$N$6:$N$1000,Assignments!$B$6:$B$1000,$A38,Assignments!$E$6:$E$1000,"Completed"),"")) | K38: =IF($A38="","",IFERROR(AVERAGEIFS(Assignments!$AO:$AO,Assignments!$B:$B,$A38,Assignments!$E:$E,"Completed"),"")) | L38: =IF($A38="","",IFERROR(COUNTIFS(Assignments!$B$6:$B$1000,$A38,Assignments!$E$6:$E$1000,"Cancelled")/MAX(1,COUNTIFS(Assignments!$B$6:$B$1000,$A38,Assignments!$E$6:$E$1000,"Completed")+COUNTIFS(Assignments!$B$6:$B$1000,$A38,Assignments!$E$6:$E$1000,"Cancelled")),"")) -> 0 | M38: =IF($A38="","",IFERROR(AVERAGEIFS(Assignments!$P$6:$P$1000,Assignments!$B$6:$B$1000,$A38,Assignments!$E$6:$E$1000,"Completed"),"")) | N38: - | P38: =IF(A38="","",MAX(0,MIN(3,SUMIFS(Strike_Log!$C:$C,Strike_Log!$B:$B,A38,Strike_Log!$A:$A,">="&IF(Config!$B$1004="Y",TODAY()-Config!$B$1005,DATE(1900,1,1)),Strike_Log!$I:$I,1)))) -> 0 | Q38: =IF(P38="",0,CHOOSE(MIN(3,MAX(0,P38))+1,0,0.03,0.07,0.2)) -> 0 | R38: =IF(A38="","",IFERROR(AVERAGEIFS(Assignments!$J:$J,Assignments!$B:$B,A38,Assignments!$E:$E,"Completed"),"")) | S38: =IF(A38="","",COUNTIFS(Assignments!$B:$B,A38,Assignments!$AE:$AE, "Y",Assignments!$D:$D,">="&TODAY()-30)) -> 0 | T38: =IF(A38="","",COUNTIFS(Assignments!$AF:$AF,A38,Assignments!$AE:$AE, "Y",Assignments!$D:$D,">="&TODAY()-30)) -> 0 | U38: =IF(A38="","",IFERROR(S38/MAX(1,COUNTIFS(Assignments!$B:$B,A38,Assignments!$D:$D,">="&TODAY()-30)),"")) -> 0 | V38: =IF(A38="","",T38-S38) -> 0
A39: GRD-36 | B39: xoticashes | C39: Regular | D39: =IF($C39="Regular","3","5") -> 3 | E39: =IF($A39="","",COUNTIFS(Assignments!$B$6:$B$305,$A39,Assignments!$E$6:$E$305,"Active")) -> 0 | F39: =IF($A39="","",COUNTIFS(Assignments!$B$6:$B$305,$A39,Assignments!$D$6:$D$305,">="&Config!$B$3-7,Assignments!$D$6:$D$305,"<="&Config!$B$3)) -> 0 | G39: =IF($A39="","",MAXIFS(Assignments!$D$6:$D$305,Assignments!$B$6:$B$305,$A39)) -> 0 | H39: =IF($A39="","",IF($G39="","",Config!$B$3-$G39)) -> 46071 | I39: =IF($A39="","",IF($D39=0,"",$E39/$D39)) -> 0 | J39: =IF($A39="","",IFERROR(AVERAGEIFS(Assignments!$N$6:$N$1000,Assignments!$B$6:$B$1000,$A39,Assignments!$E$6:$E$1000,"Completed"),"")) | K39: =IF($A39="","",IFERROR(AVERAGEIFS(Assignments!$AO:$AO,Assignments!$B:$B,$A39,Assignments!$E:$E,"Completed"),"")) | L39: =IF($A39="","",IFERROR(COUNTIFS(Assignments!$B$6:$B$1000,$A39,Assignments!$E$6:$E$1000,"Cancelled")/MAX(1,COUNTIFS(Assignments!$B$6:$B$1000,$A39,Assignments!$E$6:$E$1000,"Completed")+COUNTIFS(Assignments!$B$6:$B$1000,$A39,Assignments!$E$6:$E$1000,"Cancelled")),"")) -> 0 | M39: =IF($A39="","",IFERROR(AVERAGEIFS(Assignments!$P$6:$P$1000,Assignments!$B$6:$B$1000,$A39,Assignments!$E$6:$E$1000,"Completed"),"")) | N39: - | P39: =IF(A39="","",MAX(0,MIN(3,SUMIFS(Strike_Log!$C:$C,Strike_Log!$B:$B,A39,Strike_Log!$A:$A,">="&IF(Config!$B$1004="Y",TODAY()-Config!$B$1005,DATE(1900,1,1)),Strike_Log!$I:$I,1)))) -> 0 | Q39: =IF(P39="",0,CHOOSE(MIN(3,MAX(0,P39))+1,0,0.03,0.07,0.2)) -> 0 | R39: =IF(A39="","",IFERROR(AVERAGEIFS(Assignments!$J:$J,Assignments!$B:$B,A39,Assignments!$E:$E,"Completed"),"")) | S39: =IF(A39="","",COUNTIFS(Assignments!$B:$B,A39,Assignments!$AE:$AE, "Y",Assignments!$D:$D,">="&TODAY()-30)) -> 0 | T39: =IF(A39="","",COUNTIFS(Assignments!$AF:$AF,A39,Assignments!$AE:$AE, "Y",Assignments!$D:$D,">="&TODAY()-30)) -> 0 | U39: =IF(A39="","",IFERROR(S39/MAX(1,COUNTIFS(Assignments!$B:$B,A39,Assignments!$D:$D,">="&TODAY()-30)),"")) -> 0 | V39: =IF(A39="","",T39-S39) -> 0
A40: GRD-37 | B40: kolioh | C40: Regular | D40: =IF($C40="Regular","3","5") -> 3 | E40: =IF($A40="","",COUNTIFS(Assignments!$B$6:$B$305,$A40,Assignments!$E$6:$E$305,"Active")) -> 0 | F40: =IF($A40="","",COUNTIFS(Assignments!$B$6:$B$305,$A40,Assignments!$D$6:$D$305,">="&Config!$B$3-7,Assignments!$D$6:$D$305,"<="&Config!$B$3)) -> 0 | G40: =IF($A40="","",MAXIFS(Assignments!$D$6:$D$305,Assignments!$B$6:$B$305,$A40)) -> 0 | H40: =IF($A40="","",IF($G40="","",Config!$B$3-$G40)) -> 46071 | I40: =IF($A40="","",IF($D40=0,"",$E40/$D40)) -> 0 | J40: =IF($A40="","",IFERROR(AVERAGEIFS(Assignments!$N$6:$N$1000,Assignments!$B$6:$B$1000,$A40,Assignments!$E$6:$E$1000,"Completed"),"")) | K40: =IF($A40="","",IFERROR(AVERAGEIFS(Assignments!$AO:$AO,Assignments!$B:$B,$A40,Assignments!$E:$E,"Completed"),"")) | L40: =IF($A40="","",IFERROR(COUNTIFS(Assignments!$B$6:$B$1000,$A40,Assignments!$E$6:$E$1000,"Cancelled")/MAX(1,COUNTIFS(Assignments!$B$6:$B$1000,$A40,Assignments!$E$6:$E$1000,"Completed")+COUNTIFS(Assignments!$B$6:$B$1000,$A40,Assignments!$E$6:$E$1000,"Cancelled")),"")) -> 0 | M40: =IF($A40="","",IFERROR(AVERAGEIFS(Assignments!$P$6:$P$1000,Assignments!$B$6:$B$1000,$A40,Assignments!$E$6:$E$1000,"Completed"),"")) | N40: - | P40: =IF(A40="","",MAX(0,MIN(3,SUMIFS(Strike_Log!$C:$C,Strike_Log!$B:$B,A40,Strike_Log!$A:$A,">="&IF(Config!$B$1004="Y",TODAY()-Config!$B$1005,DATE(1900,1,1)),Strike_Log!$I:$I,1)))) -> 0 | Q40: =IF(P40="",0,CHOOSE(MIN(3,MAX(0,P40))+1,0,0.03,0.07,0.2)) -> 0 | R40: =IF(A40="","",IFERROR(AVERAGEIFS(Assignments!$J:$J,Assignments!$B:$B,A40,Assignments!$E:$E,"Completed"),"")) | S40: =IF(A40="","",COUNTIFS(Assignments!$B:$B,A40,Assignments!$AE:$AE, "Y",Assignments!$D:$D,">="&TODAY()-30)) -> 0 | T40: =IF(A40="","",COUNTIFS(Assignments!$AF:$AF,A40,Assignments!$AE:$AE, "Y",Assignments!$D:$D,">="&TODAY()-30)) -> 0 | U40: =IF(A40="","",IFERROR(S40/MAX(1,COUNTIFS(Assignments!$B:$B,A40,Assignments!$D:$D,">="&TODAY()-30)),"")) -> 0 | V40: =IF(A40="","",T40-S40) -> 0
A41: GRD-38 | B41: korean_zombiie | C41: Regular | D41: =IF($C41="Regular","3","5") -> 3 | E41: =IF($A41="","",COUNTIFS(Assignments!$B$6:$B$305,$A41,Assignments!$E$6:$E$305,"Active")) -> 0 | F41: =IF($A41="","",COUNTIFS(Assignments!$B$6:$B$305,$A41,Assignments!$D$6:$D$305,">="&Config!$B$3-7,Assignments!$D$6:$D$305,"<="&Config!$B$3)) -> 0 | G41: =IF($A41="","",MAXIFS(Assignments!$D$6:$D$305,Assignments!$B$6:$B$305,$A41)) -> 0 | H41: =IF($A41="","",IF($G41="","",Config!$B$3-$G41)) -> 46071 | I41: =IF($A41="","",IF($D41=0,"",$E41/$D41)) -> 0 | J41: =IF($A41="","",IFERROR(AVERAGEIFS(Assignments!$N$6:$N$1000,Assignments!$B$6:$B$1000,$A41,Assignments!$E$6:$E$1000,"Completed"),"")) | K41: =IF($A41="","",IFERROR(AVERAGEIFS(Assignments!$AO:$AO,Assignments!$B:$B,$A41,Assignments!$E:$E,"Completed"),"")) | L41: =IF($A41="","",IFERROR(COUNTIFS(Assignments!$B$6:$B$1000,$A41,Assignments!$E$6:$E$1000,"Cancelled")/MAX(1,COUNTIFS(Assignments!$B$6:$B$1000,$A41,Assignments!$E$6:$E$1000,"Completed")+COUNTIFS(Assignments!$B$6:$B$1000,$A41,Assignments!$E$6:$E$1000,"Cancelled")),"")) -> 0 | M41: =IF($A41="","",IFERROR(AVERAGEIFS(Assignments!$P$6:$P$1000,Assignments!$B$6:$B$1000,$A41,Assignments!$E$6:$E$1000,"Completed"),"")) | N41: - | P41: =IF(A41="","",MAX(0,MIN(3,SUMIFS(Strike_Log!$C:$C,Strike_Log!$B:$B,A41,Strike_Log!$A:$A,">="&IF(Config!$B$1004="Y",TODAY()-Config!$B$1005,DATE(1900,1,1)),Strike_Log!$I:$I,1)))) -> 0 | Q41: =IF(P41="",0,CHOOSE(MIN(3,MAX(0,P41))+1,0,0.03,0.07,0.2)) -> 0 | R41: =IF(A41="","",IFERROR(AVERAGEIFS(Assignments!$J:$J,Assignments!$B:$B,A41,Assignments!$E:$E,"Completed"),"")) | S41: =IF(A41="","",COUNTIFS(Assignments!$B:$B,A41,Assignments!$AE:$AE, "Y",Assignments!$D:$D,">="&TODAY()-30)) -> 0 | T41: =IF(A41="","",COUNTIFS(Assignments!$AF:$AF,A41,Assignments!$AE:$AE, "Y",Assignments!$D:$D,">="&TODAY()-30)) -> 0 | U41: =IF(A41="","",IFERROR(S41/MAX(1,COUNTIFS(Assignments!$B:$B,A41,Assignments!$D:$D,">="&TODAY()-30)),"")) -> 0 | V41: =IF(A41="","",T41-S41) -> 0
A42: GRD-39 | B42: savage_telly | C42: Regular | D42: =IF($C42="Regular","3","5") -> 3 | E42: =IF($A42="","",COUNTIFS(Assignments!$B$6:$B$305,$A42,Assignments!$E$6:$E$305,"Active")) -> 0 | F42: =IF($A42="","",COUNTIFS(Assignments!$B$6:$B$305,$A42,Assignments!$D$6:$D$305,">="&Config!$B$3-7,Assignments!$D$6:$D$305,"<="&Config!$B$3)) -> 0 | G42: =IF($A42="","",MAXIFS(Assignments!$D$6:$D$305,Assignments!$B$6:$B$305,$A42)) -> 0 | H42: =IF($A42="","",IF($G42="","",Config!$B$3-$G42)) -> 46071 | I42: =IF($A42="","",IF($D42=0,"",$E42/$D42)) -> 0 | J42: =IF($A42="","",IFERROR(AVERAGEIFS(Assignments!$N$6:$N$1000,Assignments!$B$6:$B$1000,$A42,Assignments!$E$6:$E$1000,"Completed"),"")) | K42: =IF($A42="","",IFERROR(AVERAGEIFS(Assignments!$AO:$AO,Assignments!$B:$B,$A42,Assignments!$E:$E,"Completed"),"")) | L42: =IF($A42="","",IFERROR(COUNTIFS(Assignments!$B$6:$B$1000,$A42,Assignments!$E$6:$E$1000,"Cancelled")/MAX(1,COUNTIFS(Assignments!$B$6:$B$1000,$A42,Assignments!$E$6:$E$1000,"Completed")+COUNTIFS(Assignments!$B$6:$B$1000,$A42,Assignments!$E$6:$E$1000,"Cancelled")),"")) -> 0 | M42: =IF($A42="","",IFERROR(AVERAGEIFS(Assignments!$P$6:$P$1000,Assignments!$B$6:$B$1000,$A42,Assignments!$E$6:$E$1000,"Completed"),"")) | N42: - | P42: =IF(A42="","",MAX(0,MIN(3,SUMIFS(Strike_Log!$C:$C,Strike_Log!$B:$B,A42,Strike_Log!$A:$A,">="&IF(Config!$B$1004="Y",TODAY()-Config!$B$1005,DATE(1900,1,1)),Strike_Log!$I:$I,1)))) -> 0 | Q42: =IF(P42="",0,CHOOSE(MIN(3,MAX(0,P42))+1,0,0.03,0.07,0.2)) -> 0 | R42: =IF(A42="","",IFERROR(AVERAGEIFS(Assignments!$J:$J,Assignments!$B:$B,A42,Assignments!$E:$E,"Completed"),"")) | S42: =IF(A42="","",COUNTIFS(Assignments!$B:$B,A42,Assignments!$AE:$AE, "Y",Assignments!$D:$D,">="&TODAY()-30)) -> 0 | T42: =IF(A42="","",COUNTIFS(Assignments!$AF:$AF,A42,Assignments!$AE:$AE, "Y",Assignments!$D:$D,">="&TODAY()-30)) -> 0 | U42: =IF(A42="","",IFERROR(S42/MAX(1,COUNTIFS(Assignments!$B:$B,A42,Assignments!$D:$D,">="&TODAY()-30)),"")) -> 0 | V42: =IF(A42="","",T42-S42) -> 0
A43: GRD-40 | B43: notravelcalls | C43: Regular | D43: =IF($C43="Regular","3","5") -> 3 | E43: =IF($A43="","",COUNTIFS(Assignments!$B$6:$B$305,$A43,Assignments!$E$6:$E$305,"Active")) -> 0 | F43: =IF($A43="","",COUNTIFS(Assignments!$B$6:$B$305,$A43,Assignments!$D$6:$D$305,">="&Config!$B$3-7,Assignments!$D$6:$D$305,"<="&Config!$B$3)) -> 0 | G43: =IF($A43="","",MAXIFS(Assignments!$D$6:$D$305,Assignments!$B$6:$B$305,$A43)) -> 0 | H43: =IF($A43="","",IF($G43="","",Config!$B$3-$G43)) -> 46071 | I43: =IF($A43="","",IF($D43=0,"",$E43/$D43)) -> 0 | J43: =IF($A43="","",IFERROR(AVERAGEIFS(Assignments!$N$6:$N$1000,Assignments!$B$6:$B$1000,$A43,Assignments!$E$6:$E$1000,"Completed"),"")) | K43: =IF($A43="","",IFERROR(AVERAGEIFS(Assignments!$AO:$AO,Assignments!$B:$B,$A43,Assignments!$E:$E,"Completed"),"")) | L43: =IF($A43="","",IFERROR(COUNTIFS(Assignments!$B$6:$B$1000,$A43,Assignments!$E$6:$E$1000,"Cancelled")/MAX(1,COUNTIFS(Assignments!$B$6:$B$1000,$A43,Assignments!$E$6:$E$1000,"Completed")+COUNTIFS(Assignments!$B$6:$B$1000,$A43,Assignments!$E$6:$E$1000,"Cancelled")),"")) -> 0 | M43: =IF($A43="","",IFERROR(AVERAGEIFS(Assignments!$P$6:$P$1000,Assignments!$B$6:$B$1000,$A43,Assignments!$E$6:$E$1000,"Completed"),"")) | N43: - | P43: =IF(A43="","",MAX(0,MIN(3,SUMIFS(Strike_Log!$C:$C,Strike_Log!$B:$B,A43,Strike_Log!$A:$A,">="&IF(Config!$B$1004="Y",TODAY()-Config!$B$1005,DATE(1900,1,1)),Strike_Log!$I:$I,1)))) -> 0 | Q43: =IF(P43="",0,CHOOSE(MIN(3,MAX(0,P43))+1,0,0.03,0.07,0.2)) -> 0 | R43: =IF(A43="","",IFERROR(AVERAGEIFS(Assignments!$J:$J,Assignments!$B:$B,A43,Assignments!$E:$E,"Completed"),"")) | S43: =IF(A43="","",COUNTIFS(Assignments!$B:$B,A43,Assignments!$AE:$AE, "Y",Assignments!$D:$D,">="&TODAY()-30)) -> 0 | T43: =IF(A43="","",COUNTIFS(Assignments!$AF:$AF,A43,Assignments!$AE:$AE, "Y",Assignments!$D:$D,">="&TODAY()-30)) -> 0 | U43: =IF(A43="","",IFERROR(S43/MAX(1,COUNTIFS(Assignments!$B:$B,A43,Assignments!$D:$D,">="&TODAY()-30)),"")) -> 0 | V43: =IF(A43="","",T43-S43) -> 0
A44: GRD-41 | B44: rookietolegend | C44: Regular | D44: =IF($C44="Regular","3","5") -> 3 | E44: =IF($A44="","",COUNTIFS(Assignments!$B$6:$B$305,$A44,Assignments!$E$6:$E$305,"Active")) -> 0 | F44: =IF($A44="","",COUNTIFS(Assignments!$B$6:$B$305,$A44,Assignments!$D$6:$D$305,">="&Config!$B$3-7,Assignments!$D$6:$D$305,"<="&Config!$B$3)) -> 0 | G44: =IF($A44="","",MAXIFS(Assignments!$D$6:$D$305,Assignments!$B$6:$B$305,$A44)) -> 0 | H44: =IF($A44="","",IF($G44="","",Config!$B$3-$G44)) -> 46071 | I44: =IF($A44="","",IF($D44=0,"",$E44/$D44)) -> 0 | J44: =IF($A44="","",IFERROR(AVERAGEIFS(Assignments!$N$6:$N$1000,Assignments!$B$6:$B$1000,$A44,Assignments!$E$6:$E$1000,"Completed"),"")) | K44: =IF($A44="","",IFERROR(AVERAGEIFS(Assignments!$AO:$AO,Assignments!$B:$B,$A44,Assignments!$E:$E,"Completed"),"")) | L44: =IF($A44="","",IFERROR(COUNTIFS(Assignments!$B$6:$B$1000,$A44,Assignments!$E$6:$E$1000,"Cancelled")/MAX(1,COUNTIFS(Assignments!$B$6:$B$1000,$A44,Assignments!$E$6:$E$1000,"Completed")+COUNTIFS(Assignments!$B$6:$B$1000,$A44,Assignments!$E$6:$E$1000,"Cancelled")),"")) -> 0 | M44: =IF($A44="","",IFERROR(AVERAGEIFS(Assignments!$P$6:$P$1000,Assignments!$B$6:$B$1000,$A44,Assignments!$E$6:$E$1000,"Completed"),"")) | N44: - | P44: =IF(A44="","",MAX(0,MIN(3,SUMIFS(Strike_Log!$C:$C,Strike_Log!$B:$B,A44,Strike_Log!$A:$A,">="&IF(Config!$B$1004="Y",TODAY()-Config!$B$1005,DATE(1900,1,1)),Strike_Log!$I:$I,1)))) -> 0 | Q44: =IF(P44="",0,CHOOSE(MIN(3,MAX(0,P44))+1,0,0.03,0.07,0.2)) -> 0 | R44: =IF(A44="","",IFERROR(AVERAGEIFS(Assignments!$J:$J,Assignments!$B:$B,A44,Assignments!$E:$E,"Completed"),"")) | S44: =IF(A44="","",COUNTIFS(Assignments!$B:$B,A44,Assignments!$AE:$AE, "Y",Assignments!$D:$D,">="&TODAY()-30)) -> 0 | T44: =IF(A44="","",COUNTIFS(Assignments!$AF:$AF,A44,Assignments!$AE:$AE, "Y",Assignments!$D:$D,">="&TODAY()-30)) -> 0 | U44: =IF(A44="","",IFERROR(S44/MAX(1,COUNTIFS(Assignments!$B:$B,A44,Assignments!$D:$D,">="&TODAY()-30)),"")) -> 0 | V44: =IF(A44="","",T44-S44) -> 0
A45: GRD-42 | B45: nxsty4487 | C45: Regular | D45: =IF($C45="Regular","3","5") -> 3 | E45: =IF($A45="","",COUNTIFS(Assignments!$B$6:$B$305,$A45,Assignments!$E$6:$E$305,"Active")) -> 0 | F45: =IF($A45="","",COUNTIFS(Assignments!$B$6:$B$305,$A45,Assignments!$D$6:$D$305,">="&Config!$B$3-7,Assignments!$D$6:$D$305,"<="&Config!$B$3)) -> 0 | G45: =IF($A45="","",MAXIFS(Assignments!$D$6:$D$305,Assignments!$B$6:$B$305,$A45)) -> 0 | H45: =IF($A45="","",IF($G45="","",Config!$B$3-$G45)) -> 46071 | I45: =IF($A45="","",IF($D45=0,"",$E45/$D45)) -> 0 | J45: =IF($A45="","",IFERROR(AVERAGEIFS(Assignments!$N$6:$N$1000,Assignments!$B$6:$B$1000,$A45,Assignments!$E$6:$E$1000,"Completed"),"")) | K45: =IF($A45="","",IFERROR(AVERAGEIFS(Assignments!$AO:$AO,Assignments!$B:$B,$A45,Assignments!$E:$E,"Completed"),"")) | L45: =IF($A45="","",IFERROR(COUNTIFS(Assignments!$B$6:$B$1000,$A45,Assignments!$E$6:$E$1000,"Cancelled")/MAX(1,COUNTIFS(Assignments!$B$6:$B$1000,$A45,Assignments!$E$6:$E$1000,"Completed")+COUNTIFS(Assignments!$B$6:$B$1000,$A45,Assignments!$E$6:$E$1000,"Cancelled")),"")) -> 0 | M45: =IF($A45="","",IFERROR(AVERAGEIFS(Assignments!$P$6:$P$1000,Assignments!$B$6:$B$1000,$A45,Assignments!$E$6:$E$1000,"Completed"),"")) | N45: - | P45: =IF(A45="","",MAX(0,MIN(3,SUMIFS(Strike_Log!$C:$C,Strike_Log!$B:$B,A45,Strike_Log!$A:$A,">="&IF(Config!$B$1004="Y",TODAY()-Config!$B$1005,DATE(1900,1,1)),Strike_Log!$I:$I,1)))) -> 0 | Q45: =IF(P45="",0,CHOOSE(MIN(3,MAX(0,P45))+1,0,0.03,0.07,0.2)) -> 0 | R45: =IF(A45="","",IFERROR(AVERAGEIFS(Assignments!$J:$J,Assignments!$B:$B,A45,Assignments!$E:$E,"Completed"),"")) | S45: =IF(A45="","",COUNTIFS(Assignments!$B:$B,A45,Assignments!$AE:$AE, "Y",Assignments!$D:$D,">="&TODAY()-30)) -> 0 | T45: =IF(A45="","",COUNTIFS(Assignments!$AF:$AF,A45,Assignments!$AE:$AE, "Y",Assignments!$D:$D,">="&TODAY()-30)) -> 0 | U45: =IF(A45="","",IFERROR(S45/MAX(1,COUNTIFS(Assignments!$B:$B,A45,Assignments!$D:$D,">="&TODAY()-30)),"")) -> 0 | V45: =IF(A45="","",T45-S45) -> 0
A46: GRD-43 | B46: idk566784 | C46: Regular | D46: =IF($C46="Regular","3","5") -> 3 | E46: =IF($A46="","",COUNTIFS(Assignments!$B$6:$B$305,$A46,Assignments!$E$6:$E$305,"Active")) -> 0 | F46: =IF($A46="","",COUNTIFS(Assignments!$B$6:$B$305,$A46,Assignments!$D$6:$D$305,">="&Config!$B$3-7,Assignments!$D$6:$D$305,"<="&Config!$B$3)) -> 0 | G46: =IF($A46="","",MAXIFS(Assignments!$D$6:$D$305,Assignments!$B$6:$B$305,$A46)) -> 0 | H46: =IF($A46="","",IF($G46="","",Config!$B$3-$G46)) -> 46071 | I46: =IF($A46="","",IF($D46=0,"",$E46/$D46)) -> 0 | J46: =IF($A46="","",IFERROR(AVERAGEIFS(Assignments!$N$6:$N$1000,Assignments!$B$6:$B$1000,$A46,Assignments!$E$6:$E$1000,"Completed"),"")) | K46: =IF($A46="","",IFERROR(AVERAGEIFS(Assignments!$AO:$AO,Assignments!$B:$B,$A46,Assignments!$E:$E,"Completed"),"")) | L46: =IF($A46="","",IFERROR(COUNTIFS(Assignments!$B$6:$B$1000,$A46,Assignments!$E$6:$E$1000,"Cancelled")/MAX(1,COUNTIFS(Assignments!$B$6:$B$1000,$A46,Assignments!$E$6:$E$1000,"Completed")+COUNTIFS(Assignments!$B$6:$B$1000,$A46,Assignments!$E$6:$E$1000,"Cancelled")),"")) -> 0 | M46: =IF($A46="","",IFERROR(AVERAGEIFS(Assignments!$P$6:$P$1000,Assignments!$B$6:$B$1000,$A46,Assignments!$E$6:$E$1000,"Completed"),"")) | N46: - | P46: =IF(A46="","",MAX(0,MIN(3,SUMIFS(Strike_Log!$C:$C,Strike_Log!$B:$B,A46,Strike_Log!$A:$A,">="&IF(Config!$B$1004="Y",TODAY()-Config!$B$1005,DATE(1900,1,1)),Strike_Log!$I:$I,1)))) -> 0 | Q46: =IF(P46="",0,CHOOSE(MIN(3,MAX(0,P46))+1,0,0.03,0.07,0.2)) -> 0 | R46: =IF(A46="","",IFERROR(AVERAGEIFS(Assignments!$J:$J,Assignments!$B:$B,A46,Assignments!$E:$E,"Completed"),"")) | S46: =IF(A46="","",COUNTIFS(Assignments!$B:$B,A46,Assignments!$AE:$AE, "Y",Assignments!$D:$D,">="&TODAY()-30)) -> 0 | T46: =IF(A46="","",COUNTIFS(Assignments!$AF:$AF,A46,Assignments!$AE:$AE, "Y",Assignments!$D:$D,">="&TODAY()-30)) -> 0 | U46: =IF(A46="","",IFERROR(S46/MAX(1,COUNTIFS(Assignments!$B:$B,A46,Assignments!$D:$D,">="&TODAY()-30)),"")) -> 0 | V46: =IF(A46="","",T46-S46) -> 0
A47: GRD-44 | B47: plqckss | C47: Elite | D47: =IF($C47="Regular","3","5") -> 5 | E47: =IF($A47="","",COUNTIFS(Assignments!$B$6:$B$305,$A47,Assignments!$E$6:$E$305,"Active")) -> 0 | F47: =IF($A47="","",COUNTIFS(Assignments!$B$6:$B$305,$A47,Assignments!$D$6:$D$305,">="&Config!$B$3-7,Assignments!$D$6:$D$305,"<="&Config!$B$3)) -> 0 | G47: =IF($A47="","",MAXIFS(Assignments!$D$6:$D$305,Assignments!$B$6:$B$305,$A47)) -> 0 | H47: =IF($A47="","",IF($G47="","",Config!$B$3-$G47)) -> 46071 | I47: =IF($A47="","",IF($D47=0,"",$E47/$D47)) -> 0 | J47: =IF($A47="","",IFERROR(AVERAGEIFS(Assignments!$N$6:$N$1000,Assignments!$B$6:$B$1000,$A47,Assignments!$E$6:$E$1000,"Completed"),"")) | K47: =IF($A47="","",IFERROR(AVERAGEIFS(Assignments!$AO:$AO,Assignments!$B:$B,$A47,Assignments!$E:$E,"Completed"),"")) | L47: =IF($A47="","",IFERROR(COUNTIFS(Assignments!$B$6:$B$1000,$A47,Assignments!$E$6:$E$1000,"Cancelled")/MAX(1,COUNTIFS(Assignments!$B$6:$B$1000,$A47,Assignments!$E$6:$E$1000,"Completed")+COUNTIFS(Assignments!$B$6:$B$1000,$A47,Assignments!$E$6:$E$1000,"Cancelled")),"")) -> 0 | M47: =IF($A47="","",IFERROR(AVERAGEIFS(Assignments!$P$6:$P$1000,Assignments!$B$6:$B$1000,$A47,Assignments!$E$6:$E$1000,"Completed"),"")) | N47: - | P47: =IF(A47="","",MAX(0,MIN(3,SUMIFS(Strike_Log!$C:$C,Strike_Log!$B:$B,A47,Strike_Log!$A:$A,">="&IF(Config!$B$1004="Y",TODAY()-Config!$B$1005,DATE(1900,1,1)),Strike_Log!$I:$I,1)))) -> 0 | Q47: =IF(P47="",0,CHOOSE(MIN(3,MAX(0,P47))+1,0,0.03,0.07,0.2)) -> 0 | R47: =IF(A47="","",IFERROR(AVERAGEIFS(Assignments!$J:$J,Assignments!$B:$B,A47,Assignments!$E:$E,"Completed"),"")) | S47: =IF(A47="","",COUNTIFS(Assignments!$B:$B,A47,Assignments!$AE:$AE, "Y",Assignments!$D:$D,">="&TODAY()-30)) -> 0 | T47: =IF(A47="","",COUNTIFS(Assignments!$AF:$AF,A47,Assignments!$AE:$AE, "Y",Assignments!$D:$D,">="&TODAY()-30)) -> 0 | U47: =IF(A47="","",IFERROR(S47/MAX(1,COUNTIFS(Assignments!$B:$B,A47,Assignments!$D:$D,">="&TODAY()-30)),"")) -> 0 | V47: =IF(A47="","",T47-S47) -> 0
